<mujoco model="panda">

  <compiler angle="radian" meshdir="assets" autolimits="true"/>

  <option cone="elliptic" impratio="10"/>
  <!--<option integrator="RK4" timestep="0.001"/>-->

  <default>
    <default class="visual">
      <geom type="mesh" contype="0" conaffinity="0" group="2"/>
    </default>
      
    <default class="collision">
      <geom type="mesh" contype="1" conaffinity="2" group="3"/>
    </default>
  
    <default class="panda">
      <material specular="0.5" shininess="0.25"/>
      <joint armature="0.1" damping="1" axis="0 0 1" range="-2.8973 2.8973"/>
      <general dyntype="none" biastype="affine" ctrlrange="-2.8973 2.8973" forcerange="-87 87"/>
      <position forcerange="-100 100"/>
      <default class="finger">
        <joint axis="0 1 0" type="slide" range="0 0.04"/>
      </default>

      <default class="panda_visual">
        <geom material="off_white" mesh="link1"/>
      </default>
      <default class="panda_collision">
        <geom group="3" type="mesh" contype="1" conaffinity="2"/>
      </default>
    </default>

    <default class="allegro_right">
      <joint axis="0 1 0" damping=".1"/>
      <position kp="1"/>
      <geom density="800"/>

      <default class="allegro_visual">
        <geom type="mesh" contype="0" conaffinity="0" group="2" material="black"/>
          
        <default class="palm_visual">
          <geom mesh="base_link"/>
        </default>
        <default class="base_visual">
          <geom mesh="link_0.0"/>
        </default>
        <default class="proximal_visual">
          <geom mesh="link_1.0"/>
        </default>
        <default class="medial_visual">
          <geom mesh="link_2.0"/>
        </default>
        <default class="distal_visual">
          <geom mesh="link_3.0"/>
        </default>
        <default class="fingertip_visual">
          <geom mesh="link_3.0_tip"/>
        </default>
        <default class="thumbtip_visual">
          <geom mesh="link_15.0_tip"/>
        </default>
      </default>

      <default class="allegro_collision">
        <geom group="3" type="box" mass="0" contype="1" conaffinity="2"/>
        <default class="palm_collision">
          <geom size="0.0204 0.0565 0.0475" pos="-0.0093 0 -0.0475"/>
        </default>
        <default class="base_collision">
          <geom size="0.0098 0.01375 0.0082" pos="0 0 0.0082"/>
          <default class="thumb_base_collision">
            <geom size="0.0179 0.017 0.02275" pos="-0.0179 0.009 0.0145"/>
          </default>
        </default>
        <default class="proximal_collision">
          <geom size="0.0098 0.01375 0.027" pos="0 0 0.027"/>
          <default class="thumb_proximal_collision">
            <geom size="0.0098 0.01375 0.00885" pos="0 0 0.00885"/>
          </default>
        </default>
        <default class="medial_collision">
          <geom size="0.0098 0.01375 0.0192" pos="0 0 0.0192"/>
          <default class="thumb_medial_collision">
            <geom size="0.0098 0.01375 0.0257" pos="0 0 0.0257"/>
          </default>
        </default>
        <default class="distal_collision">
          <geom size="0.0098 0.01375 0.008" pos="0 0 0.008"/>
          <default class="thumb_distal_collision">
            <geom size="0.0098 0.01375 0.0157" pos="0 0 0.0157"/>
          </default>
        </default>
        <default class="fingertip_collision">
          <geom type="capsule" size="0.012 0.01" pos="0 0 -0.01"/> <!-- pos="0 0 -0.01"-->
          <default class="thumbtip_collision">
            <geom type="capsule" size="0.012 0.008" pos="0 0 -0.008"/> <!-- pos="0 0 -0.008"-->
          </default>
        </default>
      </default>

      <default class="base">
        <joint axis="0 0 1" range="-0.47 0.47"/>
        <position ctrlrange="-0.47 0.47"/>
      </default>
      <default class="proximal">
        <joint range="-0.196 1.61"/>
        <position ctrlrange="-0.196 1.61"/>
      </default>
      <default class="medial">
        <joint range="-0.174 1.709"/>
        <position ctrlrange="-0.174 1.709"/>
      </default>
      <default class="distal">
        <joint range="-0.227 1.618"/>
        <position ctrlrange="-0.227 1.618"/>
      </default>
      <default class="thumb_base">
        <joint axis="-1 0 0" range="0.263 1.396"/>
        <position ctrlrange="0.263 1.396"/>
      </default>
      <default class="thumb_proximal">
        <joint axis="0 0 1" range="-0.105 1.163"/>
        <position ctrlrange="-0.105 1.163"/>
      </default>
      <default class="thumb_medial">
        <joint range="-0.189 1.644"/>
        <position ctrlrange="-0.189 1.644"/>
      </default>
      <default class="thumb_distal">
        <joint range="-0.162 1.719"/>
        <position ctrlrange="-0.162 1.719"/>
      </default>
    </default>
    
    <geom solref="0.01 1" solimp="0.95 0.995 0.001"/> <!-- solref="time constant - damping" solimp="begin of sr - end of sr - min force scale"-->
  </default>

  <asset>
    <material name="groundplane" rgba="0.8 0.8 0.8 1"/>

    <material class="panda" name="white" rgba="1 1 1 1"/>
    <material class="panda" name="off_white" rgba="0.901961 0.921569 0.929412 1"/>
    <material class="panda" name="black" rgba="0.25 0.25 0.25 1"/>
    <material class="panda" name="green" rgba="0 1 0 1"/>
    <material class="panda" name="light_blue" rgba="0.039216 0.541176 0.780392 1"/>

    <!-- Collision meshes -->
    <mesh name="link0_c" file="link0.stl"/>
    <mesh name="link1_c" file="link1.stl"/>
    <mesh name="link2_c" file="link2.stl"/>
    <mesh name="link3_c" file="link3.stl"/>
    <mesh name="link4_c" file="link4.stl"/>
    <mesh name="link5_c0" file="link5_collision_0.obj"/>
    <mesh name="link5_c1" file="link5_collision_1.obj"/>
    <mesh name="link5_c2" file="link5_collision_2.obj"/>
    <mesh name="link6_c" file="link6.stl"/>
    <mesh name="link7_c" file="link7.stl"/>

    <!-- Visual meshes -->
    <mesh name="link0_0" file="link0_0.obj"/>
    <mesh name="link0_1" file="link0_1.obj"/>
    <mesh name="link0_2" file="link0_2.obj"/>
    <mesh name="link0_3" file="link0_3.obj"/>
    <mesh name="link0_4" file="link0_4.obj"/>
    <mesh name="link0_5" file="link0_5.obj"/>
    <mesh name="link0_7" file="link0_7.obj"/>
    <mesh name="link0_8" file="link0_8.obj"/>
    <mesh name="link0_9" file="link0_9.obj"/>
    <mesh name="link0_10" file="link0_10.obj"/>
    <mesh name="link0_11" file="link0_11.obj"/>
    <mesh name="link1" file="link1.obj"/>
    <mesh name="link2" file="link2.obj"/>
    <mesh name="link3_0" file="link3_0.obj"/>
    <mesh name="link3_1" file="link3_1.obj"/>
    <mesh name="link3_2" file="link3_2.obj"/>
    <mesh name="link3_3" file="link3_3.obj"/>
    <mesh name="link4_0" file="link4_0.obj"/>
    <mesh name="link4_1" file="link4_1.obj"/>
    <mesh name="link4_2" file="link4_2.obj"/>
    <mesh name="link4_3" file="link4_3.obj"/>
    <mesh name="link5_0" file="link5_0.obj"/>
    <mesh name="link5_1" file="link5_1.obj"/>
    <mesh name="link5_2" file="link5_2.obj"/>
    <mesh name="link6_0" file="link6_0.obj"/>
    <mesh name="link6_1" file="link6_1.obj"/>
    <mesh name="link6_2" file="link6_2.obj"/>
    <mesh name="link6_3" file="link6_3.obj"/>
    <mesh name="link6_4" file="link6_4.obj"/>
    <mesh name="link6_5" file="link6_5.obj"/>
    <mesh name="link6_6" file="link6_6.obj"/>
    <mesh name="link6_7" file="link6_7.obj"/>
    <mesh name="link6_8" file="link6_8.obj"/>
    <mesh name="link6_9" file="link6_9.obj"/>
    <mesh name="link6_10" file="link6_10.obj"/>
    <mesh name="link6_11" file="link6_11.obj"/>
    <mesh name="link6_12" file="link6_12.obj"/>
    <mesh name="link6_13" file="link6_13.obj"/>
    <mesh name="link6_14" file="link6_14.obj"/>
    <mesh name="link6_15" file="link6_15.obj"/>
    <mesh name="link6_16" file="link6_16.obj"/>
    <mesh name="link7_0" file="link7_0.obj"/>
    <mesh name="link7_1" file="link7_1.obj"/>
    <mesh name="link7_2" file="link7_2.obj"/>
    <mesh name="link7_3" file="link7_3.obj"/>
    <mesh name="link7_4" file="link7_4.obj"/>
    <mesh name="link7_5" file="link7_5.obj"/>
    <mesh name="link7_6" file="link7_6.obj"/>
    <mesh name="link7_7" file="link7_7.obj"/>

    <material name="black2" rgba="0.2 0.2 0.2 1"/>
    <material name="white2" rgba="0.9 0.9 0.9 1"/>

    <mesh name="base_link" file="base_link.stl"/>
    <mesh name="link_0.0" file="link_0.0.stl"/>
    <mesh name="link_1.0" file="link_1.0.stl"/>
    <mesh name="link_2.0" file="link_2.0.stl"/>
    <mesh name="link_3.0" file="link_3.0.stl"/>
    <mesh name="link_3.0_tip" file="link_3.0_tip.stl"/>
    <mesh name="link_12.0_right" file="link_12.0_right.stl"/>
    <mesh name="link_13.0" file="link_13.0.stl"/>
    <mesh name="link_14.0" file="link_14.0.stl"/>
    <mesh name="link_15.0" file="link_15.0.stl"/>
    <mesh name="link_15.0_tip" file="link_15.0_tip.stl"/>
    
    <mesh name="th_tip_collision" file="th_tip_collision.stl"/>
  </asset>

  <worldbody>
    <camera name="maincam" mode= "fixed" fovy="75" euler="0 0 0" pos="0 0 0"/>
    <light pos="0 0 1"/>
    <light pos="0.3 0 1.5" dir="0 0 -1" directional="true"/>
    <geom name="floor" pos="0 0 0" size="0 0 0.05" type="plane" material="groundplane"/>
    <!--<geom name="ground" type="plane" pos="0 0 0" size="2 2 0.1" rgba="0.8 0.8 0.8 1"/>-->
    <!--<light name="light1" pos="0 0 3" dir="0 0 -1" diffuse="0.5 0.5 0.5" specular="0.1 0.1 0.1" directional="true"/>-->
    <!--<light name="top" pos="0 0 2" mode="trackcom"/>-->
    <body name="brick" pos="0.79 0.0 0.05">
      <freejoint/>
      <geom name="brick_geom" type="box" size="0.045 0.03 0.025"
            rgba="0.8 0.3 0.1 1" mass="0.2"
            contype="1" conaffinity="1"
            solref="0.01 1" solimp="0.95 0.995 0.001"/>
    </body>
    <body name="link0" childclass="panda">
      <inertial mass="0.629769" pos="-0.041018 -0.00014 0.049974"
        fullinertia="0.00315 0.00388 0.004285 8.2904e-7 0.00015 8.2299e-6"/>
      <geom mesh="link0_0" material="off_white" class="visual"/>
      <geom mesh="link0_1" material="black" class="visual"/>
      <geom mesh="link0_2" material="off_white" class="visual"/>
      <geom mesh="link0_3" material="black" class="visual"/>
      <geom mesh="link0_4" material="off_white" class="visual"/>
      <geom mesh="link0_5" material="black" class="visual"/>
      <geom mesh="link0_7" material="white" class="visual"/>
      <geom mesh="link0_8" material="white" class="visual"/>
      <geom mesh="link0_9" material="black" class="visual"/>
      <geom mesh="link0_10" material="off_white" class="visual"/>
      <geom mesh="link0_11" material="white" class="visual"/>
      <geom mesh="link0_c" class="panda_collision"/>
      <body name="link1" pos="0 0 0.333">
        <inertial mass="4.970684" pos="0.003875 0.002081 -0.04762"
          fullinertia="0.70337 0.70661 0.0091170 -0.00013900 0.0067720 0.019169"/>
        <joint name="joint1" damping="40"/>
        <geom material="white" mesh="link1" class="visual"/>
        <geom mesh="link1_c" class="panda_collision"/>
        <body name="link2" quat="1 -1 0 0">
          <inertial mass="0.646926" pos="-0.003141 -0.02872 0.003495"
            fullinertia="0.0079620 2.8110e-2 2.5995e-2 -3.925e-3 1.0254e-2 7.04e-4"/>
          <joint name="joint2" range="-1.7628 1.7628" damping="40"/>
          <geom material="white" mesh="link2" class="visual"/>
          <geom mesh="link2_c" class="panda_collision"/>
          <body name="link3" pos="0 -0.316 0" quat="1 1 0 0">
            <joint name="joint3" damping="40"/>
            <inertial mass="3.228604" pos="2.7518e-2 3.9252e-2 -6.6502e-2"
              fullinertia="3.7242e-2 3.6155e-2 1.083e-2 -4.761e-3 -1.1396e-2 -1.2805e-2"/>
            <geom mesh="link3_0" material="white" class="visual"/>
            <geom mesh="link3_1" material="white" class="visual"/>
            <geom mesh="link3_2" material="white" class="visual"/>
            <geom mesh="link3_3" material="black" class="visual"/>
            <geom mesh="link3_c" class="panda_collision"/>
            <body name="link4" pos="0.0825 0 0" quat="1 1 0 0">
              <inertial mass="3.587895" pos="-5.317e-2 1.04419e-1 2.7454e-2"
                fullinertia="2.5853e-2 1.9552e-2 2.8323e-2 7.796e-3 -1.332e-3 8.641e-3"/>
              <joint name="joint4" range="-3.0718 -0.0698" damping="40"/>
              <geom mesh="link4_0" material="white" class="visual"/>
              <geom mesh="link4_1" material="white" class="visual"/>
              <geom mesh="link4_2" material="black" class="visual"/>
              <geom mesh="link4_3" material="white" class="visual"/>
              <geom mesh="link4_c" class="panda_collision"/>
              <body name="link5" pos="-0.0825 0.384 0" quat="1 -1 0 0">
                <inertial mass="1.225946" pos="-1.1953e-2 4.1065e-2 -3.8437e-2"
                  fullinertia="3.5549e-2 2.9474e-2 8.627e-3 -2.117e-3 -4.037e-3 2.29e-4"/>
                <joint name="joint5" damping="2"/>
                <geom mesh="link5_0" material="black" class="visual"/>
                <geom mesh="link5_1" material="white" class="visual"/>
                <geom mesh="link5_2" material="white" class="visual"/>
                <geom mesh="link5_c0" class="panda_collision"/>
                <geom mesh="link5_c1" class="panda_collision"/>
                <geom mesh="link5_c2" class="panda_collision"/>
                <body name="link6" quat="1 1 0 0">
                  <inertial mass="1.666555" pos="6.0149e-2 -1.4117e-2 -1.0517e-2"
                    fullinertia="1.964e-3 4.354e-3 5.433e-3 1.09e-4 -1.158e-3 3.41e-4"/>
                  <joint name="joint6" range="-0.0175 3.7525" damping="2"/>
                  <geom mesh="link6_0" material="off_white" class="visual"/>
                  <geom mesh="link6_1" material="white" class="visual"/>
                  <geom mesh="link6_2" material="black" class="visual"/>
                  <geom mesh="link6_3" material="white" class="visual"/>
                  <geom mesh="link6_4" material="white" class="visual"/>
                  <geom mesh="link6_5" material="white" class="visual"/>
                  <geom mesh="link6_6" material="white" class="visual"/>
                  <geom mesh="link6_7" material="light_blue" class="visual"/>
                  <geom mesh="link6_8" material="light_blue" class="visual"/>
                  <geom mesh="link6_9" material="black" class="visual"/>
                  <geom mesh="link6_10" material="black" class="visual"/>
                  <geom mesh="link6_11" material="white" class="visual"/>
                  <geom mesh="link6_12" material="green" class="visual"/>
                  <geom mesh="link6_13" material="white" class="visual"/>
                  <geom mesh="link6_14" material="black" class="visual"/>
                  <geom mesh="link6_15" material="black" class="visual"/>
                  <geom mesh="link6_16" material="white" class="visual"/>
                  <geom mesh="link6_c" class="panda_collision"/>
                  <body name="link7" pos="0.088 0 0" quat="1 1 0 0">
                    <inertial mass="7.35522e-01" pos="1.0517e-2 -4.252e-3 6.1597e-2"
                      fullinertia="1.2516e-2 1.0027e-2 4.815e-3 -4.28e-4 -1.196e-3 -7.41e-4"/>
                    <joint name="joint7" damping="2"/>
                    <geom mesh="link7_0" material="white" class="visual"/>
                    <geom mesh="link7_1" material="black" class="visual"/>
                    <geom mesh="link7_2" material="black" class="visual"/>
                    <geom mesh="link7_3" material="black" class="visual"/>
                    <geom mesh="link7_4" material="black" class="visual"/>
                    <geom mesh="link7_5" material="black" class="visual"/>
                    <geom mesh="link7_6" material="black" class="visual"/>
                    <geom mesh="link7_7" material="white" class="visual"/>
                    <geom mesh="link7_c" class="panda_collision"/>
                    <body name="palm" pos="-0.0075 0 0.20175" quat="0 0 0 1" childclass="allegro_right">
                      <inertial mass="0.4154" pos="0 0 0.0475" diaginertia="1e-4 1e-4 1e-4"/>
                      <geom class="visual" mesh="base_link"/>
                      <geom class="palm_collision"/>
                      <!-- First finger -->
                      <body name="ff_base" pos="0 0.0435 -0.001542" quat="0.999048 -0.0436194 0 0">
                        <joint name="ffj0" class="base"/>
                        <geom class="visual" mesh="link_0.0"/>
                        <geom class="base_collision"/>
                        <body name="ff_proximal" pos="0 0 0.0164">
                          <joint name="ffj1" class="proximal"/>
                          <geom class="visual" mesh="link_1.0"/>
                          <geom class="proximal_collision"/>
                          <body name="ff_medial" pos="0 0 0.054">
                            <joint name="ffj2" class="medial"/>
                            <geom class="visual" mesh="link_2.0"/>
                            <geom class="medial_collision"/>
                            <body name="ff_distal" pos="0 0 0.0384">
                              <joint name="ffj3" class="distal"/>
                              <geom class="visual" mesh="link_3.0"/>
                              <geom class="distal_collision"/>
                              <body name="ff_tip" pos="0 0 0.0265">
                                <geom class="visual" mesh="link_3.0_tip" material="white2"/>
                                <geom class="fingertip_collision"/>
                                <site name="ff_tip_site" pos="0 0 0.005" size="0.005" rgba="0 1 0 1"/>
                                <camera name="ff_gelsight" pos="0 0 0.002" euler=" 0 3.14159 0" fovy="60" mode="fixed"/>
                                <light name="ff_gel_light" pos="0 0 0.003" dir="0 0 1" diffuse="1 1 1" specular="0.5 0.5 0.5" castshadow="false"/>
                              </body>
                            </body>
                          </body>
                        </body>
                      </body>
                      <!-- Middle finger -->
                      <body name="mf_base" pos="0 0 0.0007">
                        <joint name="mfj0" class="base"/>
                        <geom class="visual" mesh="link_0.0"/>
                        <geom class="base_collision"/>
                        <body name="mf_proximal" pos="0 0 0.0164">
                          <joint name="mfj1" class="proximal"/>
                          <geom class="visual" mesh="link_1.0"/>
                          <geom class="proximal_collision"/>
                          <body name="mf_medial" pos="0 0 0.054">
                            <joint name="mfj2" class="medial"/>
                            <geom class="visual" mesh="link_2.0"/>
                            <geom class="medial_collision"/>
                            <body name="mf_distal" pos="0 0 0.0384">
                              <joint name="mfj3" class="distal"/>
                              <geom class="visual" mesh="link_3.0"/>
                              <geom class="distal_collision"/>
                              <body name="mf_tip" pos="0 0 0.0265">
                                <geom class="visual" mesh="link_3.0_tip" material="white2"/>
                                <geom class="fingertip_collision"/>
                                <site name="mf_tip_site" pos=" 0 0 0.005" size="0.005" rgba="0 1 0 1"/>
                                <camera name="mf_gelsight" pos="0 0 0.002" euler="0 3.14159 0" fovy="60" mode="fixed"/>
                                <light name="mf_gel_light" pos="0 0 0.003" dir="0 0 1" diffuse="1 1 1" specular="0.5 0.5 0.5" castshadow="false"/>
                              </body>
                            </body>
                          </body>
                        </body>
                      </body>
                      <!-- Ring finger -->
                      <body name="rf_base" pos="0 -0.0435 -0.001542" quat="0.999048 0.0436194 0 0">
                        <joint name="rfj0" class="base"/>
                        <geom class="visual" mesh="link_0.0"/>
                        <geom class="base_collision"/>
                        <body name="rf_proximal" pos="0 0 0.0164">
                          <joint name="rfj1" class="proximal"/>
                          <geom class="visual" mesh="link_1.0"/>
                          <geom class="proximal_collision"/>
                          <body name="rf_medial" pos="0 0 0.054">
                            <joint name="rfj2" class="medial"/>
                            <geom class="visual" mesh="link_2.0"/>
                            <geom class="medial_collision"/>
                            <body name="rf_distal" pos="0 0 0.0384">
                              <joint name="rfj3" class="distal"/>
                              <geom class="visual" mesh="link_3.0"/>
                              <geom class="distal_collision"/>
                              <body name="rf_tip" pos="0 0 0.0265">
                                <geom class="visual" mesh="link_3.0_tip" material="white2"/>
                                <geom class="fingertip_collision"/>
                                <site name="rf_tip_site" pos=" 0 0 0.005" size="0.005" rgba="0 1 0 1"/>
                                <camera name="rf_gelsight" pos="0 0 0.002" euler="0 3.14159 0" fovy="60" mode="fixed"/>
                                <light name="rf_gel_light" pos="0 0 0.003" dir="0 0 1" diffuse="1 1 1" specular="0.5 0.5 0.5" castshadow="false"/>
                              </body>
                            </body>
                          </body>
                        </body>
                      </body>
                      <!-- Thumb -->
                      <body name="th_base" pos="-0.0182 0.019333 -0.045987" quat="0.477714 -0.521334 -0.521334 -0.477714">
                        <joint name="thj0" class="thumb_base"/>
                        <geom class="visual" mesh="link_12.0_right"/>
                        <geom class="thumb_base_collision"/>
                        <body name="th_proximal" pos="-0.027 0.005 0.0399">
                          <joint name="thj1" class="thumb_proximal"/>
                          <geom class="visual" mesh="link_13.0"/>
                          <geom class="thumb_proximal_collision"/>
                          <body name="th_medial" pos="0 0 0.0177">
                            <joint name="thj2" class="thumb_medial"/>
                            <geom class="visual" mesh="link_14.0"/>
                            <geom class="thumb_medial_collision"/>
                            <body name="th_distal" pos="0 0 0.0514">
                              <joint name="thj3" class="thumb_distal"/>
                              <geom class="visual" mesh="link_15.0"/>
                              <geom class="thumb_distal_collision"/>
                              <body name="th_tip" pos="0 0 0.0422">
                                <geom class="visual" mesh="link_15.0_tip" material="white2"/>
                                <geom class="thumbtip_collision"/>
                                <site name="th_tip_site" pos=" 0 0 0.005" size="0.005" rgba="0 1 0 1"/>
                                <camera name="th_gelsight" pos="0 0 0.002" euler="0 3.14159 0" fovy="60" mode="fixed"/>
                                <light name="th_gel_light" pos="0 0 0.003" dir="0 0 1" diffuse="1 1 1" specular="0.5 0.5 0.5" castshadow="false"/>
                              </body>
                            </body>
                          </body>
                        </body>
                      </body>
                    </body>
                  </body>
                </body>
              </body>
            </body>
          </body>
        </body>
      </body>
    </body>
  </worldbody>

  <contact>
    <exclude body1="palm" body2="ff_base"/>
    <exclude body1="palm" body2="mf_base"/>
    <exclude body1="palm" body2="rf_base"/>
    <exclude body1="palm" body2="th_base"/>
    <exclude body1="palm" body2="th_proximal"/>
    <exclude body1="link0" body2="link1"/>
    <exclude body1="link1" body2="link2"/>
    <exclude body1="link2" body2="link3"/>
    <exclude body1="link3" body2="link4"/>
    <exclude body1="link4" body2="link5"/>
    <exclude body1="link5" body2="link6"/>
    <exclude body1="link6" body2="link7"/>
    <exclude body1="ff_base" body2="ff_proximal"/>
    <exclude body1="ff_proximal" body2="ff_medial"/>
    <exclude body1="ff_medial" body2="ff_distal"/>
    <exclude body1="ff_distal" body2="ff_tip"/>
    <exclude body1="mf_base" body2="mf_proximal"/>
    <exclude body1="mf_proximal" body2="mf_medial"/>
    <exclude body1="mf_medial" body2="mf_distal"/>
    <exclude body1="mf_distal" body2="mf_tip"/>
    <exclude body1="rf_base" body2="rf_proximal"/>
    <exclude body1="rf_proximal" body2="rf_medial"/>
    <exclude body1="rf_medial" body2="rf_distal"/>
    <exclude body1="rf_distal" body2="rf_tip"/>
    <exclude body1="th_base" body2="th_proximal"/>
    <exclude body1="th_proximal" body2="th_medial"/>
    <exclude body1="th_medial" body2="th_distal"/>
    <exclude body1="th_distal" body2="th_tip"/>
  </contact>

  <actuator>
    <position class="panda" name="actuator1" joint="joint1" kp="1000" kv="20"
     ctrlrange="-2.8973 2.8973"/>
    <position class="panda" name="actuator2" joint="joint2" kp="1000" kv="20"
     ctrlrange="-1.7628 1.7628"/>
    <position class="panda" name="actuator3" joint="joint3" kp="750" kv="4"
     ctrlrange="-2.8973 2.8973"/>
    <position class="panda" name="actuator4" joint="joint4" kp="750" kv="4"
     ctrlrange="-3.0718 -0.0698"/>
    <position class="panda" name="actuator5" joint="joint5" kp="300" kv="2"
     forcerange="-12 12" ctrlrange="-2.8973 2.8973"/>
    <position class="panda" name="actuator6" joint="joint6" kp="300" kv="2" forcerange="-12 12"
      ctrlrange="-0.0175 3.7525"/>
    <position class="panda" name="actuator7" joint="joint7" kp="300" kv="2" forcerange="-12 12"/>
    <position name="ffa0" joint="ffj0" class="base" kp="30" ctrlrange="-1.5 1.5"/>
    <position name="ffa1" joint="ffj1" class="proximal" kp="30" ctrlrange="-1.5 1.5"/>
    <position name="ffa2" joint="ffj2" class="medial" kp="30" ctrlrange="-1.5 1.5"/>
    <position name="ffa3" joint="ffj3" class="distal" kp="30" ctrlrange="-1.5 1.5"/>
    <position name="mfa0" joint="mfj0" class="base" kp="30" ctrlrange="-1.5 1.5"/>
    <position name="mfa1" joint="mfj1" class="proximal" kp="30" ctrlrange="-1.5 1.5"/>
    <position name="mfa2" joint="mfj2" class="medial" kp="30" ctrlrange="-1.5 1.5"/>
    <position name="mfa3" joint="mfj3" class="distal" kp="30" ctrlrange="-1.5 1.5"/>
    <position name="rfa0" joint="rfj0" class="base" kp="30" ctrlrange="-1.5 1.5"/>
    <position name="rfa1" joint="rfj1" class="proximal" kp="30" ctrlrange="-1.5 1.5"/>
    <position name="rfa2" joint="rfj2" class="medial" kp="30" ctrlrange="-1.5 1.5"/>
    <position name="rfa3" joint="rfj3" class="distal" kp="30" ctrlrange="-1.5 1.5"/>
    <position name="tha0" joint="thj0" class="thumb_base" kp="30" ctrlrange="-1.5 1.5"/>
    <position name="tha1" joint="thj1" class="thumb_proximal" kp="30" ctrlrange="-1.5 1.5"/>
    <position name="tha2" joint="thj2" class="thumb_medial" kp="30" ctrlrange="-1.5 1.5"/>
    <position name="tha3" joint="thj3" class="thumb_distal" kp="30" ctrlrange="-1.5 1.5"/>
  </actuator>
  
  <sensor>
    <force name="ff_tip_contact" site="ff_tip_site"/>
    <force name="mf_tip_contact" site="mf_tip_site"/>
    <force name="rf_tip_contact" site="rf_tip_site"/>
    <force name="th_tip_contact" site="th_tip_site"/>
    
    <!--<touch name="ff_tip_contact" site="ff_tip_site"/>-->
    <!--<touch name="mf_tip_contact" site="ff_tip_site"/>-->
    <!--<touch name="rf_tip_contact" site="ff_tip_site"/>-->
    <!--<touch name="th_tip_contact" site="ff_tip_site"/>-->
  </sensor>

</mujoco>
